[2025-10-02T22:55:42.204+0000] {processor.py:161} INFO - Started process (PID=7757) to work on /opt/airflow/dags/dag2.py
[2025-10-02T22:55:42.207+0000] {processor.py:830} INFO - Processing file /opt/airflow/dags/dag2.py for tasks to queue
[2025-10-02T22:55:42.213+0000] {logging_mixin.py:188} INFO - [2025-10-02T22:55:42.212+0000] {dagbag.py:545} INFO - Filling up the DagBag from /opt/airflow/dags/dag2.py
[2025-10-02T22:55:42.278+0000] {logging_mixin.py:188} INFO - [2025-10-02T22:55:42.257+0000] {dagbag.py:355} ERROR - Failed to import: /opt/airflow/dags/dag2.py
Traceback (most recent call last):
  File "/home/airflow/.local/lib/python3.12/site-packages/airflow/models/dagbag.py", line 351, in parse
    loader.exec_module(new_module)
  File "<frozen importlib._bootstrap_external>", line 995, in exec_module
  File "<frozen importlib._bootstrap>", line 488, in _call_with_frames_removed
  File "/opt/airflow/dags/dag2.py", line 9, in <module>
    start_date=datetime(2025,10,3),
               ^^^^^^^^
NameError: name 'datetime' is not defined. Did you forget to import 'datetime'
[2025-10-02T22:55:42.289+0000] {processor.py:842} WARNING - No viable dags retrieved from /opt/airflow/dags/dag2.py
[2025-10-02T22:55:42.335+0000] {processor.py:183} INFO - Processing /opt/airflow/dags/dag2.py took 0.149 seconds
[2025-10-02T22:56:12.817+0000] {processor.py:161} INFO - Started process (PID=7811) to work on /opt/airflow/dags/dag2.py
[2025-10-02T22:56:12.825+0000] {processor.py:830} INFO - Processing file /opt/airflow/dags/dag2.py for tasks to queue
[2025-10-02T22:56:12.832+0000] {logging_mixin.py:188} INFO - [2025-10-02T22:56:12.831+0000] {dagbag.py:545} INFO - Filling up the DagBag from /opt/airflow/dags/dag2.py
[2025-10-02T22:56:12.925+0000] {logging_mixin.py:188} INFO - [2025-10-02T22:56:12.906+0000] {dagbag.py:355} ERROR - Failed to import: /opt/airflow/dags/dag2.py
Traceback (most recent call last):
  File "/home/airflow/.local/lib/python3.12/site-packages/airflow/models/dagbag.py", line 351, in parse
    loader.exec_module(new_module)
  File "<frozen importlib._bootstrap_external>", line 995, in exec_module
  File "<frozen importlib._bootstrap>", line 488, in _call_with_frames_removed
  File "/opt/airflow/dags/dag2.py", line 9, in <module>
    start_date=datetime(2025,10,3),
               ^^^^^^^^
NameError: name 'datetime' is not defined. Did you forget to import 'datetime'
[2025-10-02T22:56:12.941+0000] {processor.py:842} WARNING - No viable dags retrieved from /opt/airflow/dags/dag2.py
[2025-10-02T22:56:13.013+0000] {processor.py:183} INFO - Processing /opt/airflow/dags/dag2.py took 0.240 seconds
[2025-10-02T22:56:43.335+0000] {processor.py:161} INFO - Started process (PID=7865) to work on /opt/airflow/dags/dag2.py
[2025-10-02T22:56:43.338+0000] {processor.py:830} INFO - Processing file /opt/airflow/dags/dag2.py for tasks to queue
[2025-10-02T22:56:43.343+0000] {logging_mixin.py:188} INFO - [2025-10-02T22:56:43.343+0000] {dagbag.py:545} INFO - Filling up the DagBag from /opt/airflow/dags/dag2.py
[2025-10-02T22:56:43.396+0000] {logging_mixin.py:188} INFO - [2025-10-02T22:56:43.381+0000] {dagbag.py:355} ERROR - Failed to import: /opt/airflow/dags/dag2.py
Traceback (most recent call last):
  File "/home/airflow/.local/lib/python3.12/site-packages/airflow/models/dagbag.py", line 351, in parse
    loader.exec_module(new_module)
  File "<frozen importlib._bootstrap_external>", line 995, in exec_module
  File "<frozen importlib._bootstrap>", line 488, in _call_with_frames_removed
  File "/opt/airflow/dags/dag2.py", line 9, in <module>
    start_date=datetime(2025,10,3),
               ^^^^^^^^
NameError: name 'datetime' is not defined. Did you forget to import 'datetime'
[2025-10-02T22:56:43.404+0000] {processor.py:842} WARNING - No viable dags retrieved from /opt/airflow/dags/dag2.py
[2025-10-02T22:56:43.450+0000] {processor.py:183} INFO - Processing /opt/airflow/dags/dag2.py took 0.133 seconds
[2025-10-02T22:57:13.759+0000] {processor.py:161} INFO - Started process (PID=7919) to work on /opt/airflow/dags/dag2.py
[2025-10-02T22:57:13.761+0000] {processor.py:830} INFO - Processing file /opt/airflow/dags/dag2.py for tasks to queue
[2025-10-02T22:57:13.766+0000] {logging_mixin.py:188} INFO - [2025-10-02T22:57:13.765+0000] {dagbag.py:545} INFO - Filling up the DagBag from /opt/airflow/dags/dag2.py
[2025-10-02T22:57:13.815+0000] {logging_mixin.py:188} INFO - [2025-10-02T22:57:13.801+0000] {dagbag.py:355} ERROR - Failed to import: /opt/airflow/dags/dag2.py
Traceback (most recent call last):
  File "/home/airflow/.local/lib/python3.12/site-packages/airflow/models/dagbag.py", line 351, in parse
    loader.exec_module(new_module)
  File "<frozen importlib._bootstrap_external>", line 995, in exec_module
  File "<frozen importlib._bootstrap>", line 488, in _call_with_frames_removed
  File "/opt/airflow/dags/dag2.py", line 9, in <module>
    start_date=datetime(2025,10,3),
               ^^^^^^^^
NameError: name 'datetime' is not defined. Did you forget to import 'datetime'
[2025-10-02T22:57:13.826+0000] {processor.py:842} WARNING - No viable dags retrieved from /opt/airflow/dags/dag2.py
[2025-10-02T22:57:13.874+0000] {processor.py:183} INFO - Processing /opt/airflow/dags/dag2.py took 0.131 seconds
[2025-10-02T22:57:44.112+0000] {processor.py:161} INFO - Started process (PID=7973) to work on /opt/airflow/dags/dag2.py
[2025-10-02T22:57:44.115+0000] {processor.py:830} INFO - Processing file /opt/airflow/dags/dag2.py for tasks to queue
[2025-10-02T22:57:44.120+0000] {logging_mixin.py:188} INFO - [2025-10-02T22:57:44.119+0000] {dagbag.py:545} INFO - Filling up the DagBag from /opt/airflow/dags/dag2.py
[2025-10-02T22:57:44.170+0000] {logging_mixin.py:188} INFO - [2025-10-02T22:57:44.153+0000] {dagbag.py:355} ERROR - Failed to import: /opt/airflow/dags/dag2.py
Traceback (most recent call last):
  File "/home/airflow/.local/lib/python3.12/site-packages/airflow/models/dagbag.py", line 351, in parse
    loader.exec_module(new_module)
  File "<frozen importlib._bootstrap_external>", line 995, in exec_module
  File "<frozen importlib._bootstrap>", line 488, in _call_with_frames_removed
  File "/opt/airflow/dags/dag2.py", line 9, in <module>
    start_date=datetime(2025,10,3),
               ^^^^^^^^
NameError: name 'datetime' is not defined. Did you forget to import 'datetime'
[2025-10-02T22:57:44.178+0000] {processor.py:842} WARNING - No viable dags retrieved from /opt/airflow/dags/dag2.py
[2025-10-02T22:57:44.316+0000] {processor.py:183} INFO - Processing /opt/airflow/dags/dag2.py took 0.218 seconds
[2025-10-02T22:58:14.651+0000] {processor.py:161} INFO - Started process (PID=8027) to work on /opt/airflow/dags/dag2.py
[2025-10-02T22:58:14.653+0000] {processor.py:830} INFO - Processing file /opt/airflow/dags/dag2.py for tasks to queue
[2025-10-02T22:58:14.659+0000] {logging_mixin.py:188} INFO - [2025-10-02T22:58:14.658+0000] {dagbag.py:545} INFO - Filling up the DagBag from /opt/airflow/dags/dag2.py
[2025-10-02T22:58:14.706+0000] {logging_mixin.py:188} INFO - [2025-10-02T22:58:14.688+0000] {dagbag.py:355} ERROR - Failed to import: /opt/airflow/dags/dag2.py
Traceback (most recent call last):
  File "/home/airflow/.local/lib/python3.12/site-packages/airflow/models/dagbag.py", line 351, in parse
    loader.exec_module(new_module)
  File "<frozen importlib._bootstrap_external>", line 995, in exec_module
  File "<frozen importlib._bootstrap>", line 488, in _call_with_frames_removed
  File "/opt/airflow/dags/dag2.py", line 9, in <module>
    start_date=datetime(2025,10,3),
               ^^^^^^^^
NameError: name 'datetime' is not defined. Did you forget to import 'datetime'
[2025-10-02T22:58:14.718+0000] {processor.py:842} WARNING - No viable dags retrieved from /opt/airflow/dags/dag2.py
[2025-10-02T22:58:14.777+0000] {processor.py:183} INFO - Processing /opt/airflow/dags/dag2.py took 0.144 seconds
[2025-10-02T22:58:45.335+0000] {processor.py:161} INFO - Started process (PID=8081) to work on /opt/airflow/dags/dag2.py
[2025-10-02T22:58:45.337+0000] {processor.py:830} INFO - Processing file /opt/airflow/dags/dag2.py for tasks to queue
[2025-10-02T22:58:45.342+0000] {logging_mixin.py:188} INFO - [2025-10-02T22:58:45.341+0000] {dagbag.py:545} INFO - Filling up the DagBag from /opt/airflow/dags/dag2.py
[2025-10-02T22:58:45.387+0000] {logging_mixin.py:188} INFO - [2025-10-02T22:58:45.374+0000] {dagbag.py:355} ERROR - Failed to import: /opt/airflow/dags/dag2.py
Traceback (most recent call last):
  File "/home/airflow/.local/lib/python3.12/site-packages/airflow/models/dagbag.py", line 351, in parse
    loader.exec_module(new_module)
  File "<frozen importlib._bootstrap_external>", line 995, in exec_module
  File "<frozen importlib._bootstrap>", line 488, in _call_with_frames_removed
  File "/opt/airflow/dags/dag2.py", line 9, in <module>
    start_date=datetime(2025,10,3),
               ^^^^^^^^
NameError: name 'datetime' is not defined. Did you forget to import 'datetime'
[2025-10-02T22:58:45.395+0000] {processor.py:842} WARNING - No viable dags retrieved from /opt/airflow/dags/dag2.py
[2025-10-02T22:58:45.447+0000] {processor.py:183} INFO - Processing /opt/airflow/dags/dag2.py took 0.126 seconds
[2025-10-02T22:59:16.110+0000] {processor.py:161} INFO - Started process (PID=8135) to work on /opt/airflow/dags/dag2.py
[2025-10-02T22:59:16.115+0000] {processor.py:830} INFO - Processing file /opt/airflow/dags/dag2.py for tasks to queue
[2025-10-02T22:59:16.122+0000] {logging_mixin.py:188} INFO - [2025-10-02T22:59:16.121+0000] {dagbag.py:545} INFO - Filling up the DagBag from /opt/airflow/dags/dag2.py
[2025-10-02T22:59:16.156+0000] {logging_mixin.py:188} INFO - [2025-10-02T22:59:16.145+0000] {dagbag.py:355} ERROR - Failed to import: /opt/airflow/dags/dag2.py
Traceback (most recent call last):
  File "/home/airflow/.local/lib/python3.12/site-packages/airflow/models/dagbag.py", line 351, in parse
    loader.exec_module(new_module)
  File "<frozen importlib._bootstrap_external>", line 995, in exec_module
  File "<frozen importlib._bootstrap>", line 488, in _call_with_frames_removed
  File "/opt/airflow/dags/dag2.py", line 9, in <module>
    start_date=datetime(2025,10,3),
               ^^^^^^^^
NameError: name 'datetime' is not defined. Did you forget to import 'datetime'
[2025-10-02T22:59:16.163+0000] {processor.py:842} WARNING - No viable dags retrieved from /opt/airflow/dags/dag2.py
[2025-10-02T22:59:16.207+0000] {processor.py:183} INFO - Processing /opt/airflow/dags/dag2.py took 0.123 seconds
[2025-10-02T22:59:47.208+0000] {processor.py:161} INFO - Started process (PID=8189) to work on /opt/airflow/dags/dag2.py
[2025-10-02T22:59:47.211+0000] {processor.py:830} INFO - Processing file /opt/airflow/dags/dag2.py for tasks to queue
[2025-10-02T22:59:47.217+0000] {logging_mixin.py:188} INFO - [2025-10-02T22:59:47.216+0000] {dagbag.py:545} INFO - Filling up the DagBag from /opt/airflow/dags/dag2.py
[2025-10-02T22:59:47.262+0000] {logging_mixin.py:188} INFO - [2025-10-02T22:59:47.245+0000] {dagbag.py:355} ERROR - Failed to import: /opt/airflow/dags/dag2.py
Traceback (most recent call last):
  File "/home/airflow/.local/lib/python3.12/site-packages/airflow/models/dagbag.py", line 351, in parse
    loader.exec_module(new_module)
  File "<frozen importlib._bootstrap_external>", line 995, in exec_module
  File "<frozen importlib._bootstrap>", line 488, in _call_with_frames_removed
  File "/opt/airflow/dags/dag2.py", line 9, in <module>
    start_date=datetime(2025,10,3),
               ^^^^^^^^
NameError: name 'datetime' is not defined. Did you forget to import 'datetime'
[2025-10-02T22:59:47.270+0000] {processor.py:842} WARNING - No viable dags retrieved from /opt/airflow/dags/dag2.py
[2025-10-02T22:59:47.313+0000] {processor.py:183} INFO - Processing /opt/airflow/dags/dag2.py took 0.124 seconds
[2025-10-02T23:00:17.480+0000] {processor.py:161} INFO - Started process (PID=8243) to work on /opt/airflow/dags/dag2.py
[2025-10-02T23:00:17.482+0000] {processor.py:830} INFO - Processing file /opt/airflow/dags/dag2.py for tasks to queue
[2025-10-02T23:00:17.487+0000] {logging_mixin.py:188} INFO - [2025-10-02T23:00:17.486+0000] {dagbag.py:545} INFO - Filling up the DagBag from /opt/airflow/dags/dag2.py
[2025-10-02T23:00:17.543+0000] {logging_mixin.py:188} INFO - [2025-10-02T23:00:17.522+0000] {dagbag.py:355} ERROR - Failed to import: /opt/airflow/dags/dag2.py
Traceback (most recent call last):
  File "/home/airflow/.local/lib/python3.12/site-packages/airflow/models/dagbag.py", line 351, in parse
    loader.exec_module(new_module)
  File "<frozen importlib._bootstrap_external>", line 995, in exec_module
  File "<frozen importlib._bootstrap>", line 488, in _call_with_frames_removed
  File "/opt/airflow/dags/dag2.py", line 9, in <module>
    start_date=datetime(2025,10,3),
               ^^^^^^^^
NameError: name 'datetime' is not defined. Did you forget to import 'datetime'
[2025-10-02T23:00:17.552+0000] {processor.py:842} WARNING - No viable dags retrieved from /opt/airflow/dags/dag2.py
[2025-10-02T23:00:17.613+0000] {processor.py:183} INFO - Processing /opt/airflow/dags/dag2.py took 0.148 seconds
[2025-10-02T23:00:48.067+0000] {processor.py:161} INFO - Started process (PID=8297) to work on /opt/airflow/dags/dag2.py
[2025-10-02T23:00:48.070+0000] {processor.py:830} INFO - Processing file /opt/airflow/dags/dag2.py for tasks to queue
[2025-10-02T23:00:48.075+0000] {logging_mixin.py:188} INFO - [2025-10-02T23:00:48.074+0000] {dagbag.py:545} INFO - Filling up the DagBag from /opt/airflow/dags/dag2.py
[2025-10-02T23:00:48.121+0000] {logging_mixin.py:188} INFO - [2025-10-02T23:00:48.106+0000] {dagbag.py:355} ERROR - Failed to import: /opt/airflow/dags/dag2.py
Traceback (most recent call last):
  File "/home/airflow/.local/lib/python3.12/site-packages/airflow/models/dagbag.py", line 351, in parse
    loader.exec_module(new_module)
  File "<frozen importlib._bootstrap_external>", line 995, in exec_module
  File "<frozen importlib._bootstrap>", line 488, in _call_with_frames_removed
  File "/opt/airflow/dags/dag2.py", line 9, in <module>
    start_date=datetime(2025,10,3),
               ^^^^^^^^
NameError: name 'datetime' is not defined. Did you forget to import 'datetime'
[2025-10-02T23:00:48.139+0000] {processor.py:842} WARNING - No viable dags retrieved from /opt/airflow/dags/dag2.py
[2025-10-02T23:00:48.192+0000] {processor.py:183} INFO - Processing /opt/airflow/dags/dag2.py took 0.140 seconds
[2025-10-02T23:01:18.749+0000] {processor.py:161} INFO - Started process (PID=8351) to work on /opt/airflow/dags/dag2.py
[2025-10-02T23:01:18.753+0000] {processor.py:830} INFO - Processing file /opt/airflow/dags/dag2.py for tasks to queue
[2025-10-02T23:01:18.762+0000] {logging_mixin.py:188} INFO - [2025-10-02T23:01:18.760+0000] {dagbag.py:545} INFO - Filling up the DagBag from /opt/airflow/dags/dag2.py
[2025-10-02T23:01:18.820+0000] {logging_mixin.py:188} INFO - [2025-10-02T23:01:18.801+0000] {dagbag.py:355} ERROR - Failed to import: /opt/airflow/dags/dag2.py
Traceback (most recent call last):
  File "/home/airflow/.local/lib/python3.12/site-packages/airflow/models/dagbag.py", line 351, in parse
    loader.exec_module(new_module)
  File "<frozen importlib._bootstrap_external>", line 995, in exec_module
  File "<frozen importlib._bootstrap>", line 488, in _call_with_frames_removed
  File "/opt/airflow/dags/dag2.py", line 9, in <module>
    start_date=datetime(2025,10,3),
               ^^^^^^^^
NameError: name 'datetime' is not defined. Did you forget to import 'datetime'
[2025-10-02T23:01:18.838+0000] {processor.py:842} WARNING - No viable dags retrieved from /opt/airflow/dags/dag2.py
[2025-10-02T23:01:18.892+0000] {processor.py:183} INFO - Processing /opt/airflow/dags/dag2.py took 0.167 seconds
[2025-10-02T23:01:49.035+0000] {processor.py:161} INFO - Started process (PID=8405) to work on /opt/airflow/dags/dag2.py
[2025-10-02T23:01:49.039+0000] {processor.py:830} INFO - Processing file /opt/airflow/dags/dag2.py for tasks to queue
[2025-10-02T23:01:49.044+0000] {logging_mixin.py:188} INFO - [2025-10-02T23:01:49.043+0000] {dagbag.py:545} INFO - Filling up the DagBag from /opt/airflow/dags/dag2.py
[2025-10-02T23:01:49.095+0000] {logging_mixin.py:188} INFO - [2025-10-02T23:01:49.079+0000] {dagbag.py:355} ERROR - Failed to import: /opt/airflow/dags/dag2.py
Traceback (most recent call last):
  File "/home/airflow/.local/lib/python3.12/site-packages/airflow/models/dagbag.py", line 351, in parse
    loader.exec_module(new_module)
  File "<frozen importlib._bootstrap_external>", line 995, in exec_module
  File "<frozen importlib._bootstrap>", line 488, in _call_with_frames_removed
  File "/opt/airflow/dags/dag2.py", line 9, in <module>
    start_date=datetime(2025,10,3),
               ^^^^^^^^
NameError: name 'datetime' is not defined. Did you forget to import 'datetime'
[2025-10-02T23:01:49.104+0000] {processor.py:842} WARNING - No viable dags retrieved from /opt/airflow/dags/dag2.py
[2025-10-02T23:01:49.154+0000] {processor.py:183} INFO - Processing /opt/airflow/dags/dag2.py took 0.136 seconds
[2025-10-02T23:02:19.587+0000] {processor.py:161} INFO - Started process (PID=8459) to work on /opt/airflow/dags/dag2.py
[2025-10-02T23:02:19.590+0000] {processor.py:830} INFO - Processing file /opt/airflow/dags/dag2.py for tasks to queue
[2025-10-02T23:02:19.596+0000] {logging_mixin.py:188} INFO - [2025-10-02T23:02:19.595+0000] {dagbag.py:545} INFO - Filling up the DagBag from /opt/airflow/dags/dag2.py
[2025-10-02T23:02:19.635+0000] {logging_mixin.py:188} INFO - [2025-10-02T23:02:19.622+0000] {dagbag.py:355} ERROR - Failed to import: /opt/airflow/dags/dag2.py
Traceback (most recent call last):
  File "/home/airflow/.local/lib/python3.12/site-packages/airflow/models/dagbag.py", line 351, in parse
    loader.exec_module(new_module)
  File "<frozen importlib._bootstrap_external>", line 995, in exec_module
  File "<frozen importlib._bootstrap>", line 488, in _call_with_frames_removed
  File "/opt/airflow/dags/dag2.py", line 9, in <module>
    start_date=datetime(2025,10,3),
               ^^^^^^^^
NameError: name 'datetime' is not defined. Did you forget to import 'datetime'
[2025-10-02T23:02:19.644+0000] {processor.py:842} WARNING - No viable dags retrieved from /opt/airflow/dags/dag2.py
[2025-10-02T23:02:19.696+0000] {processor.py:183} INFO - Processing /opt/airflow/dags/dag2.py took 0.126 seconds
[2025-10-02T23:02:50.258+0000] {processor.py:161} INFO - Started process (PID=8512) to work on /opt/airflow/dags/dag2.py
[2025-10-02T23:02:50.261+0000] {processor.py:830} INFO - Processing file /opt/airflow/dags/dag2.py for tasks to queue
[2025-10-02T23:02:50.265+0000] {logging_mixin.py:188} INFO - [2025-10-02T23:02:50.265+0000] {dagbag.py:545} INFO - Filling up the DagBag from /opt/airflow/dags/dag2.py
[2025-10-02T23:02:50.323+0000] {logging_mixin.py:188} INFO - [2025-10-02T23:02:50.308+0000] {dagbag.py:355} ERROR - Failed to import: /opt/airflow/dags/dag2.py
Traceback (most recent call last):
  File "/home/airflow/.local/lib/python3.12/site-packages/airflow/models/dagbag.py", line 351, in parse
    loader.exec_module(new_module)
  File "<frozen importlib._bootstrap_external>", line 995, in exec_module
  File "<frozen importlib._bootstrap>", line 488, in _call_with_frames_removed
  File "/opt/airflow/dags/dag2.py", line 9, in <module>
    start_date=datetime(2025,10,3),
               ^^^^^^^^
NameError: name 'datetime' is not defined. Did you forget to import 'datetime'
[2025-10-02T23:02:50.330+0000] {processor.py:842} WARNING - No viable dags retrieved from /opt/airflow/dags/dag2.py
[2025-10-02T23:02:50.375+0000] {processor.py:183} INFO - Processing /opt/airflow/dags/dag2.py took 0.131 seconds
[2025-10-02T23:03:20.830+0000] {processor.py:161} INFO - Started process (PID=8566) to work on /opt/airflow/dags/dag2.py
[2025-10-02T23:03:20.835+0000] {processor.py:830} INFO - Processing file /opt/airflow/dags/dag2.py for tasks to queue
[2025-10-02T23:03:20.844+0000] {logging_mixin.py:188} INFO - [2025-10-02T23:03:20.843+0000] {dagbag.py:545} INFO - Filling up the DagBag from /opt/airflow/dags/dag2.py
[2025-10-02T23:03:20.900+0000] {logging_mixin.py:188} INFO - [2025-10-02T23:03:20.880+0000] {dagbag.py:355} ERROR - Failed to import: /opt/airflow/dags/dag2.py
Traceback (most recent call last):
  File "/home/airflow/.local/lib/python3.12/site-packages/airflow/models/dagbag.py", line 351, in parse
    loader.exec_module(new_module)
  File "<frozen importlib._bootstrap_external>", line 995, in exec_module
  File "<frozen importlib._bootstrap>", line 488, in _call_with_frames_removed
  File "/opt/airflow/dags/dag2.py", line 9, in <module>
    start_date=datetime(2025,10,3),
               ^^^^^^^^
NameError: name 'datetime' is not defined. Did you forget to import 'datetime'
[2025-10-02T23:03:20.914+0000] {processor.py:842} WARNING - No viable dags retrieved from /opt/airflow/dags/dag2.py
[2025-10-02T23:03:20.993+0000] {processor.py:183} INFO - Processing /opt/airflow/dags/dag2.py took 0.188 seconds
[2025-10-02T23:03:51.225+0000] {processor.py:161} INFO - Started process (PID=8620) to work on /opt/airflow/dags/dag2.py
[2025-10-02T23:03:51.228+0000] {processor.py:830} INFO - Processing file /opt/airflow/dags/dag2.py for tasks to queue
[2025-10-02T23:03:51.234+0000] {logging_mixin.py:188} INFO - [2025-10-02T23:03:51.233+0000] {dagbag.py:545} INFO - Filling up the DagBag from /opt/airflow/dags/dag2.py
[2025-10-02T23:03:51.283+0000] {logging_mixin.py:188} INFO - [2025-10-02T23:03:51.269+0000] {dagbag.py:355} ERROR - Failed to import: /opt/airflow/dags/dag2.py
Traceback (most recent call last):
  File "/home/airflow/.local/lib/python3.12/site-packages/airflow/models/dagbag.py", line 351, in parse
    loader.exec_module(new_module)
  File "<frozen importlib._bootstrap_external>", line 995, in exec_module
  File "<frozen importlib._bootstrap>", line 488, in _call_with_frames_removed
  File "/opt/airflow/dags/dag2.py", line 9, in <module>
    start_date=datetime(2025,10,3),
               ^^^^^^^^
NameError: name 'datetime' is not defined. Did you forget to import 'datetime'
[2025-10-02T23:03:51.291+0000] {processor.py:842} WARNING - No viable dags retrieved from /opt/airflow/dags/dag2.py
[2025-10-02T23:03:51.348+0000] {processor.py:183} INFO - Processing /opt/airflow/dags/dag2.py took 0.139 seconds
[2025-10-02T23:04:21.780+0000] {processor.py:161} INFO - Started process (PID=8675) to work on /opt/airflow/dags/dag2.py
[2025-10-02T23:04:21.783+0000] {processor.py:830} INFO - Processing file /opt/airflow/dags/dag2.py for tasks to queue
[2025-10-02T23:04:21.792+0000] {logging_mixin.py:188} INFO - [2025-10-02T23:04:21.790+0000] {dagbag.py:545} INFO - Filling up the DagBag from /opt/airflow/dags/dag2.py
[2025-10-02T23:04:21.848+0000] {logging_mixin.py:188} INFO - [2025-10-02T23:04:21.830+0000] {dagbag.py:355} ERROR - Failed to import: /opt/airflow/dags/dag2.py
Traceback (most recent call last):
  File "/home/airflow/.local/lib/python3.12/site-packages/airflow/models/dagbag.py", line 351, in parse
    loader.exec_module(new_module)
  File "<frozen importlib._bootstrap_external>", line 995, in exec_module
  File "<frozen importlib._bootstrap>", line 488, in _call_with_frames_removed
  File "/opt/airflow/dags/dag2.py", line 9, in <module>
    start_date=datetime(2025,10,3),
               ^^^^^^^^
NameError: name 'datetime' is not defined. Did you forget to import 'datetime'
[2025-10-02T23:04:21.856+0000] {processor.py:842} WARNING - No viable dags retrieved from /opt/airflow/dags/dag2.py
[2025-10-02T23:04:21.922+0000] {processor.py:183} INFO - Processing /opt/airflow/dags/dag2.py took 0.170 seconds
